<?xml version="1.0" ?>
<!-- =================================================================================== -->
<!-- |    This document was autogenerated by xacro from arm.xacro                      | -->
<!-- |    EDITING THIS FILE BY HAND IS NOT RECOMMENDED                                 | -->
<!-- =================================================================================== -->
<robot name="mulinex">
  <!-- EACH MACRO CONSISTS OF THE LINK AND ITS FOLLOWING JOINT -->
  <material name="black">
    <color rgba="0.0 0.0 0.0 1.0"/>
  </material>
  <material name="blue">
    <color rgba="0.0 0.0 0.8 1.0"/>
  </material>
  <material name="green">
    <color rgba="0.0 0.8 0.0 1.0"/>
  </material>
  <material name="grey">
    <color rgba="0.2 0.2 0.2 1.0"/>
  </material>
  <material name="orange">
    <color rgba="1.0 0.4235294117647059 0.0392156862745098 0.5"/>
  </material>
  <material name="brown">
    <color rgba="0.8705882352941177 0.8117647058823529 0.7647058823529411 1.0"/>
  </material>
  <material name="red">
    <color rgba="0.8 0.0 0.0 1.0"/>
  </material>
  <material name="white">
    <color rgba="1.0 1.0 1.0 1.0"/>
  </material>
  <link name="base_link"/>
  <joint name="JOINT_0" type="fixed">
    <parent link="base_link"/>
    <child link="MODULE_1"/>
    <origin rpy="0 0 0" xyz="0 0 0"/>
  </joint>
  <!-- Link -->
  <link name="MODULE_1">
    <visual>
      <material name="white"/>
      <origin rpy="0 0 0" xyz="0 0 0"/>
      <geometry>
        <mesh filename="package://arm_description/meshes/Module_right_front.stl"/>
      </geometry>
    </visual>
    <collision>
      <origin rpy="0 0 0" xyz="0.0945 -0.015 0"/>
      <geometry>
        <!-- <mesh filename="${arm_module_right_front}" /> -->
        <box size="0.269 0.057 0.060"/>
      </geometry>
    </collision>
    <inertial>
      <mass value="0.47669673"/>
      <origin rpy="0 0 0" xyz="7.2487360e-02 -3.1582591e-02 2.4812434e-03"/>
      <inertia ixx="2.1574269e-04" ixy="3.3437484e-05" ixz="2.4284668e-06" iyy="3.0607390e-03" iyz="-2.0388977e-06" izz="3.0504273e-03"/>
    </inertial>
  </link>
  <gazebo reference="MODULE_1">
    <material>Gazebo/White</material>
    <collision>
      <surface>
        <friction>
          <ode>
            <mu>1</mu>
            <mu2>1</mu2>
            <slip1>0</slip1>
            <slip2>0</slip2>
          </ode>
        </friction>
        <contact>
          <ode>
            <kp>1000000.0</kp>
            <kd>100.0</kd>
            <min_depth>0.001</min_depth>
          </ode>
        </contact>
      </surface>
    </collision>
  </gazebo>
  <joint name="JOINT_1" type="revolute">
    <parent link="MODULE_1"/>
    <child link="MODULE_2"/>
    <origin rpy="0 0 0" xyz="0.19 -0.044 0"/>
    <axis xyz="0 -1 0"/>
    <limit effort="2.7" lower="-3.141592" upper="3.141592" velocity="1000"/>
  </joint>
  <!-- Link -->
  <link name="MODULE_2">
    <visual>
      <material name="white"/>
      <origin rpy="0 1.570796 0" xyz="0 0 0"/>
      <geometry>
        <mesh filename="package://arm_description/meshes/Module_right_front.stl"/>
      </geometry>
    </visual>
    <collision>
      <origin rpy="0 1.570796 0" xyz="0 -0.015 -0.0945"/>
      <geometry>
        <!-- <mesh filename="${arm_module_right_front}" /> -->
        <box size="0.269 0.057 0.060"/>
      </geometry>
    </collision>
    <inertial>
      <mass value="0.47669673"/>
      <origin rpy="0 0 0" xyz="2.4812434e-03 -3.1582591e-02 -7.2487360e-02"/>
      <inertia ixx="3.0504273e-03" ixy="2.0388977e-06" ixz="-2.4284668e-06" iyy="3.0607390e-03" iyz="3.3437484e-05" izz="2.1574269e-04"/>
    </inertial>
  </link>
  <gazebo reference="MODULE_2">
    <material>Gazebo/White</material>
    <collision>
      <surface>
        <friction>
          <ode>
            <mu>1</mu>
            <mu2>1</mu2>
            <slip1>0</slip1>
            <slip2>0</slip2>
          </ode>
        </friction>
        <contact>
          <ode>
            <kp>1000000.0</kp>
            <kd>100.0</kd>
            <min_depth>0.001</min_depth>
          </ode>
        </contact>
      </surface>
    </collision>
  </gazebo>
  <joint name="JOINT_2" type="revolute">
    <parent link="MODULE_2"/>
    <child link="MODULE_3"/>
    <origin rpy="0 0 0" xyz="0 -0.044 -0.19"/>
    <axis xyz="0 -1 0"/>
    <limit effort="2.7" lower="-3.141592" upper="3.141592" velocity="1000"/>
  </joint>
  <!-- Link -->
  <link name="MODULE_3">
    <visual>
      <material name="white"/>
      <origin rpy="0 1.570796 0" xyz="0 0 0"/>
      <geometry>
        <mesh filename="package://arm_description/meshes/Module_right_front.stl"/>
      </geometry>
    </visual>
    <collision>
      <origin rpy="0 1.570796 0" xyz="0 -0.015 -0.0945"/>
      <geometry>
        <!-- <mesh filename="${arm_module_right_front}" /> -->
        <box size="0.269 0.057 0.060"/>
      </geometry>
    </collision>
    <inertial>
      <mass value="0.47669673"/>
      <origin rpy="0 0 0" xyz="2.4812434e-03 -3.1582591e-02 -7.2487360e-02"/>
      <inertia ixx="3.0504273e-03" ixy="2.0388977e-06" ixz="-2.4284668e-06" iyy="3.0607390e-03" iyz="3.3437484e-05" izz="2.1574269e-04"/>
    </inertial>
  </link>
  <gazebo reference="MODULE_3">
    <material>Gazebo/White</material>
    <collision>
      <surface>
        <friction>
          <ode>
            <mu>1</mu>
            <mu2>1</mu2>
            <slip1>0</slip1>
            <slip2>0</slip2>
          </ode>
        </friction>
        <contact>
          <ode>
            <kp>1000000.0</kp>
            <kd>100.0</kd>
            <min_depth>0.001</min_depth>
          </ode>
        </contact>
      </surface>
    </collision>
  </gazebo>
  <!-- Joint -->
  <joint name="JOINT_3" type="revolute">
    <parent link="MODULE_3"/>
    <child link="MODULE_EE"/>
    <origin rpy="0 0 0" xyz="0 -0.044 -0.19"/>
    <axis xyz="0 -1 0"/>
    <limit effort="2.7" lower="-3.141592" upper="3.141592" velocity="1000"/>
  </joint>
  <!-- EE link -->
  <link name="MODULE_EE">
    <visual>
      <material name="white"/>
      <origin rpy="0 0 0" xyz="0 0 0"/>
      <geometry>
        <mesh filename="package://arm_description/meshes/Lower_leg_right.stl"/>
      </geometry>
    </visual>
    <collision name="MODULE_EE">
      <origin rpy="0 0 0" xyz="0 0 0"/>
      <geometry>
        <mesh filename="package://arm_description/meshes/Lower_leg_right.stl"/>
      </geometry>
    </collision>
    <inertial>
      <mass value="0.046942"/>
      <origin rpy="0 0 0" xyz="-1.552593e-05 -0.0198901 -0.0660893"/>
      <inertia ixx="0.00021154" ixy="2.702972e-09" ixz="2.468115e-08" iyy="0.00021242" iyz="1.089102e-05" izz="5.140780e-06"/>
    </inertial>
  </link>
  <gazebo reference="MODULE_EE">
    <material>Gazebo/White</material>
    <collision>
      <surface>
        <friction>
          <ode>
            <mu>0.6</mu>
            <mu2>0.6</mu2>
            <slip1>0</slip1>
            <slip2>0</slip2>
          </ode>
        </friction>
        <contact>
          <ode>
            <kp>10000.0</kp>
            <kd>100.0</kd>
            <min_depth>0.001</min_depth>
          </ode>
        </contact>
      </surface>
    </collision>
  </gazebo>
  <joint name="WRIST" type="fixed">
    <parent link="MODULE_EE"/>
    <child link="EE"/>
    <origin rpy="0 0 0" xyz="0 -0.028 -0.19"/>
  </joint>
  <link name="EE">
  </link>
  <gazebo reference="$EE">
    <material>Gazebo/White</material>
    <collision>
      <surface>
        <friction>
          <ode>
            <mu>0.6</mu>
            <mu2>0.6</mu2>
            <slip1>0</slip1>
            <slip2>0</slip2>
          </ode>
        </friction>
        <contact>
          <ode>
            <kp>10000.0</kp>
            <kd>100.0</kd>
            <min_depth>0.001</min_depth>
          </ode>
        </contact>
      </surface>
    </collision>
    <sensor name="4_contactsensor_sensor" type="contact">
      <always_on>true</always_on>
      <update_rate>50</update_rate>
      <contact>
        <collision>
                            4_LOWER_LEG_fixed_joint_lump__4_FOOT_collision_1</collision>
      </contact>
    </sensor>
  </gazebo>
  <gazebo reference="base_link">
    <material>Gazebo/White</material>
  </gazebo>
  <ros2_control name="GazeboSystem" type="system">
    <hardware>
      <plugin>gazebo_ros2_control/GazeboSystem</plugin>
    </hardware>
    <joint name="JOINT_1">
      <command_interface name="effort"/>
      <state_interface name="position">
        <param name="initial_value">-0.0</param>
      </state_interface>
      <state_interface name="velocity">
        <param name="initial_value">0.0</param>
      </state_interface>
      <state_interface name="effort"/>
    </joint>
    <joint name="JOINT_2">
      <command_interface name="effort"/>
      <state_interface name="position">
        <param name="initial_value">0.0</param>
      </state_interface>
      <state_interface name="velocity">
        <param name="initial_value">0.0</param>
      </state_interface>
      <state_interface name="effort"/>
    </joint>
    <joint name="JOINT_3">
      <command_interface name="effort"/>
      <state_interface name="position">
        <param name="initial_value">0.0</param>
      </state_interface>
      <state_interface name="velocity">
        <param name="initial_value">0.0</param>
      </state_interface>
      <state_interface name="effort"/>
    </joint>
  </ros2_control>
</robot>
